Workbook

Sheet note
B1: correct cat
A2: 71 | B2: SC | C2: unlock | D2: PoolTemplate.sol | E2: Incorrect comparison, typo | F2: H-02 | G2: https://code4rena.com/reports/2022-01-insure/#h-02-typo-in-pooltemplate-unlock-function-results-in-user-being-able-to-unlock-multiple-times | H2: The line `insurances[_id].status == false;` seems to be a typo. It should probably be `insurances[_id].status = false;` since the current line is comparing the status to false but not actually changing it.
A3: 3 | B3: S3 | C3: registerTradeAndBorrow | D3: CrossMarginAccounts.sol | E3: Incorrect state update in registerTradeAndBorrow | F3: H-06 | G3: https://code4rena.com/reports/2021-04-marginswap/#h-06-users-are-credited-more-tokens-when-paying-back-debt-with-registertradeandborrow | H3: The registerTradeAndBorrow function does not correctly update the account's holdings and borrowed states, leading to potential inconsistencies in the smart contract's states.
A4: 54 | B4: SC | C4: _setKeyManagerOf | D4: MixinKeys.sol | E4: Duplicate entries in `owners` array | F4: L-24 | G4: https://code4rena.com/reports/2021-11-unlock/#overview | H4: The _setKeyManagerOf function emits the KeyManagerChanged event with the new key manager address always set to address(0). This does not accurately reflect the new key manager's address and can cause confusion for any off-chain listeners monitoring the event.

Sheet riskBugs
A1: ID | B1: Bug ID | C1: Bug Label | D1: Cat | E1: Difficulty | F1: File Name | G1: Valid | H1: Bug Description | I1: Reference | J1: Comment
A2: 3 | B2: H-02 | C2: SE-4 | D2: =IF(OR(LEFT(C2, 2)="SE", LEFT(C2, 2)="S4"), "C6", IF(LEFT(C2, 2)="S1", "C1", IF(OR(LEFT(C2, 2)="S2", LEFT(C2, 2)="S5"), "C3&5", IF(LEFT(C2, 2)="S3", "C4", IF(LEFT(C2, 2)="SC", "C7", IF(LEFT(C2, 2)="S6", "C2", "Other")))))) -> C6 | E2: 1 | F2: MarginRouter.sol | G2: native | H2: Missing fromToken != toToken check | I2: https://code4rena.com/reports/2021-04-marginswap#h-02-missing-fromtoken--totoken-check
A3: 3 | B3: H-03 | C3: S1-1 | D3: =IF(OR(LEFT(C3, 2)="SE", LEFT(C3, 2)="S4"), "C6", IF(LEFT(C3, 2)="S1", "C1", IF(OR(LEFT(C3, 2)="S2", LEFT(C3, 2)="S5"), "C3&5", IF(LEFT(C3, 2)="S3", "C4", IF(LEFT(C3, 2)="SC", "C7", IF(LEFT(C3, 2)="S6", "C2", "Other")))))) -> C1 | E3: 1 | F3: PriceAware.sol | G3: native | H3: Price feed can be manipulated | I3: https://code4rena.com/reports/2021-04-marginswap#h-03-price-feed-can-be-manipulated
A4: 3 | B4: H-04 | C4: S6-2 | D4: =IF(OR(LEFT(C4, 2)="SE", LEFT(C4, 2)="S4"), "C6", IF(LEFT(C4, 2)="S1", "C1", IF(OR(LEFT(C4, 2)="S2", LEFT(C4, 2)="S5"), "C3&5", IF(LEFT(C4, 2)="S3", "C4", IF(LEFT(C4, 2)="SC", "C7", IF(LEFT(C4, 2)="S6", "C2", "Other")))))) -> C2 | E4: 1 | F4: Lending.sol BaseLending.sol HourlyBondSubscriptionLending.sol | G4: native | H4: Inconsistent usage of applyInterest | I4: https://code4rena.com/reports/2021-04-marginswap#h-04-inconsistent-usage-of-applyinterest
A5: 3 | B5: H-05 | C5: S6-4 | D5: =IF(OR(LEFT(C5, 2)="SE", LEFT(C5, 2)="S4"), "C6", IF(LEFT(C5, 2)="S1", "C1", IF(OR(LEFT(C5, 2)="S2", LEFT(C5, 2)="S5"), "C3&5", IF(LEFT(C5, 2)="S3", "C4", IF(LEFT(C5, 2)="SC", "C7", IF(LEFT(C5, 2)="S6", "C2", "Other")))))) -> C2 | E5: 1 | F5: CrossMarginAccounts.sol | G5: native | H5: Wrong liquidation logic | I5: https://code4rena.com/reports/2021-04-marginswap#h-05-wrong-liquidation-logic
A6: 3 | B6: H-06 | C6: SC | D6: =IF(OR(LEFT(C6, 2)="SE", LEFT(C6, 2)="S4"), "C6", IF(LEFT(C6, 2)="S1", "C1", IF(OR(LEFT(C6, 2)="S2", LEFT(C6, 2)="S5"), "C3&5", IF(LEFT(C6, 2)="S3", "C4", IF(LEFT(C6, 2)="SC", "C7", IF(LEFT(C6, 2)="S6", "C2", "Other")))))) -> C7 | E6: 1 | F6: CrossMarginAccounts.sol CrossMarginTrading.sol | G6: native | H6: Users are credited more tokens when paying back debt with registerTradeAndBorrow | I6: https://code4rena.com/reports/2021-04-marginswap#h-06-users-are-credited-more-tokens-when-paying-back-debt-with-registertradeandborrow
A7: 3 | B7: H-07 | C7: S3-1 | D7: =IF(OR(LEFT(C7, 2)="SE", LEFT(C7, 2)="S4"), "C6", IF(LEFT(C7, 2)="S1", "C1", IF(OR(LEFT(C7, 2)="S2", LEFT(C7, 2)="S5"), "C3&5", IF(LEFT(C7, 2)="S3", "C4", IF(LEFT(C7, 2)="SC", "C7", IF(LEFT(C7, 2)="S6", "C2", "Other")))))) -> C4 | E7: 1 | F7: CrossMarginAccounts.sol | G7: native | H7: account.holdsToken is never set | I7: https://code4rena.com/reports/2021-04-marginswap#h-07-accountholdstoken-is-never-set
A8: 5 | B8: H-03 | C8: SC | D8: =IF(OR(LEFT(C8, 2)="SE", LEFT(C8, 2)="S4"), "C6", IF(LEFT(C8, 2)="S1", "C1", IF(OR(LEFT(C8, 2)="S2", LEFT(C8, 2)="S5"), "C3&5", IF(LEFT(C8, 2)="S3", "C4", IF(LEFT(C8, 2)="SC", "C7", IF(LEFT(C8, 2)="S6", "C2", "Other")))))) -> C7 | E8: 1 | F8: Vader.sol | G8: native | H8: Missing DAO functionality to call changeDAO() function in Vader.sol | I8: https://code4rena.com/reports/2021-04-vader#h-03-missing-dao-functionality-to-call-changedao-function-in-vadersol
A9: 5 | B9: H-04 | C9: SE-4 | D9: =IF(OR(LEFT(C9, 2)="SE", LEFT(C9, 2)="S4"), "C6", IF(LEFT(C9, 2)="S1", "C1", IF(OR(LEFT(C9, 2)="S2", LEFT(C9, 2)="S5"), "C3&5", IF(LEFT(C9, 2)="S3", "C4", IF(LEFT(C9, 2)="SC", "C7", IF(LEFT(C9, 2)="S6", "C2", "Other")))))) -> C6 | E9: 1 | F9: DAO.sol | G9: native | H9: Proposals can be cancelled | I9: https://code4rena.com/reports/2021-04-vader#h-04-proposals-can-be-cancelled
A10: 5 | B10: H-05 | C10: SE-2 | D10: =IF(OR(LEFT(C10, 2)="SE", LEFT(C10, 2)="S4"), "C6", IF(LEFT(C10, 2)="S1", "C1", IF(OR(LEFT(C10, 2)="S2", LEFT(C10, 2)="S5"), "C3&5", IF(LEFT(C10, 2)="S3", "C4", IF(LEFT(C10, 2)="SC", "C7", IF(LEFT(C10, 2)="S6", "C2", "Other")))))) -> C6 | E10: 3 | F10: DAO.sol | G10: native | H10: Flash loans can affect governance voting in DAO.sol | I10: https://code4rena.com/reports/2021-04-vader#h-05-flash-loans-can-affect-governance-voting-in-daosol
A11: 5 | B11: H-07 | C11: S6-4 | D11: =IF(OR(LEFT(C11, 2)="SE", LEFT(C11, 2)="S4"), "C6", IF(LEFT(C11, 2)="S1", "C1", IF(OR(LEFT(C11, 2)="S2", LEFT(C11, 2)="S5"), "C3&5", IF(LEFT(C11, 2)="S3", "C4", IF(LEFT(C11, 2)="SC", "C7", IF(LEFT(C11, 2)="S6", "C2", "Other")))))) -> C2 | E11: 1 | F11: Utils.sol | G11: native | H11: Wrong calcAsymmetricShare calculation | I11: https://code4rena.com/reports/2021-04-vader#h-07-wrong-calcasymmetricshare-calculation
A12: 5 | B12: H-08 | C12: S6-4 | D12: =IF(OR(LEFT(C12, 2)="SE", LEFT(C12, 2)="S4"), "C6", IF(LEFT(C12, 2)="S1", "C1", IF(OR(LEFT(C12, 2)="S2", LEFT(C12, 2)="S5"), "C3&5", IF(LEFT(C12, 2)="S3", "C4", IF(LEFT(C12, 2)="SC", "C7", IF(LEFT(C12, 2)="S6", "C2", "Other")))))) -> C2 | E12: 3 | F12: Utils.sol | G12: native | H12: Wrong liquidity units calculation | I12: https://code4rena.com/reports/2021-04-vader#h-08-wrong-liquidity-units-calculation
A13: 5 | B13: H-10 | C13: S5-3 | D13: =IF(OR(LEFT(C13, 2)="SE", LEFT(C13, 2)="S4"), "C6", IF(LEFT(C13, 2)="S1", "C1", IF(OR(LEFT(C13, 2)="S2", LEFT(C13, 2)="S5"), "C3&5", IF(LEFT(C13, 2)="S3", "C4", IF(LEFT(C13, 2)="SC", "C7", IF(LEFT(C13, 2)="S6", "C2", "Other")))))) -> C3&5 | E13: 1 | F13: Router.sol | G13: too long | H13: Anyone can list anchors / curate tokens | I13: https://code4rena.com/reports/2021-04-vader#h-10-anyone-can-list-anchors--curate-tokens
... A99: 35 | B99: H-12 | C99: S6-1 | D99: =IF(OR(LEFT(C99, 2)="SE", LEFT(C99, 2)="S4"), "C6", IF(LEFT(C99, 2)="S1", "C1", IF(OR(LEFT(C99, 2)="S2", LEFT(C99, 2)="S5"), "C3&5", IF(LEFT(C99, 2)="S3", "C4", IF(LEFT(C99, 2)="SC", "C7", IF(LEFT(C99, 2)="S6", "C2", "Other")))))) -> C2 | E99: 1 | F99: ConcentratedLiquidityPool.sol | G99: too long | H99: ConcentratedLiquidityPool: secondsPerLiquidity should be modified whenever pool liquidity changes | I99: https://code4rena.com/reports/2021-09-sushitrident-2#h-12-concentratedliquiditypool-secondsperliquidity-should-be-modified-whenever-pool-liquidity-changes
A100: 35 | B100: H-17 | C100: SC | D100: =IF(OR(LEFT(C100, 2)="SE", LEFT(C100, 2)="S4"), "C6", IF(LEFT(C100, 2)="S1", "C1", IF(OR(LEFT(C100, 2)="S2", LEFT(C100, 2)="S5"), "C3&5", IF(LEFT(C100, 2)="S3", "C4", IF(LEFT(C100, 2)="SC", "C7", IF(LEFT(C100, 2)="S6", "C2", "Other")))))) -> C7 | E100: 1 | F100: ConcentratedLiquidityPoolManager.sol ConcentratedLiquidityPosition.sol Ticks.sol | G100: native | H100: Understanding the fee growth mechanism (why nearestTick is unsuitable) | I100: https://code4rena.com/reports/2021-09-sushitrident-2#h-17-understanding-the-fee-growth-mechanism-why-nearesttick-is-unsuitable | J100: good learning material
A101: 36 | B101: H-02 | C101: S3-1 | D101: =IF(OR(LEFT(C101, 2)="SE", LEFT(C101, 2)="S4"), "C6", IF(LEFT(C101, 2)="S1", "C1", IF(OR(LEFT(C101, 2)="S2", LEFT(C101, 2)="S5"), "C3&5", IF(LEFT(C101, 2)="S3", "C4", IF(LEFT(C101, 2)="SC", "C7", IF(LEFT(C101, 2)="S6", "C2", "Other")))))) -> C4 | E101: 1 | F101: Basket.sol | G101: native | H101: Basket.sol#auctionBurn() A failed auction will freeze part of the funds | I101: https://code4rena.com/reports/2021-09-defiprotocol#h-02-basketsolauctionburn-a-failed-auction-will-freeze-part-of-the-funds
A102: 37 | B102: H-01 | C102: SC | D102: =IF(OR(LEFT(C102, 2)="SE", LEFT(C102, 2)="S4"), "C6", IF(LEFT(C102, 2)="S1", "C1", IF(OR(LEFT(C102, 2)="S2", LEFT(C102, 2)="S5"), "C3&5", IF(LEFT(C102, 2)="S3", "C4", IF(LEFT(C102, 2)="SC", "C7", IF(LEFT(C102, 2)="S6", "C2", "Other")))))) -> C7 | E102: 1 | F102: TempusController.sol | G102: compact | H102: Steal tokens from TempusController | I102: https://code4rena.com/reports/2021-10-tempus#h-01-steal-tokens-from-tempuscontroller
A103: 38 | B103: H-02 | C103: SC | D103: =IF(OR(LEFT(C103, 2)="SE", LEFT(C103, 2)="S4"), "C6", IF(LEFT(C103, 2)="S1", "C1", IF(OR(LEFT(C103, 2)="S2", LEFT(C103, 2)="S5"), "C3&5", IF(LEFT(C103, 2)="S3", "C4", IF(LEFT(C103, 2)="SC", "C7", IF(LEFT(C103, 2)="S6", "C2", "Other")))))) -> C7 | E103: 2 | F103: QuickAccManager.sol | G103: native | H103: QuickAccManager.sol#cancel() Wrong hashTx makes it impossible to cancel a scheduled transaction | I103: https://code4rena.com/reports/2021-10-ambire#h-02-quickaccmanagersolcancel-wrong-hashtx-makes-it-impossible-to-cancel-a-scheduled-transaction
A104: 38 | B104: H-03 | C104: S2-3 | D104: =IF(OR(LEFT(C104, 2)="SE", LEFT(C104, 2)="S4"), "C6", IF(LEFT(C104, 2)="S1", "C1", IF(OR(LEFT(C104, 2)="S2", LEFT(C104, 2)="S5"), "C3&5", IF(LEFT(C104, 2)="S3", "C4", IF(LEFT(C104, 2)="SC", "C7", IF(LEFT(C104, 2)="S6", "C2", "Other")))))) -> C3&5 | E104: 2 | F104: QuickAccManager.sol | G104: native | H104: Signature replay attacks for different identities (nonce on wrong party) | I104: https://code4rena.com/reports/2021-10-ambire#h-03-signature-replay-attacks-for-different-identities-nonce-on-wrong-party
A105: 38 | B105: H-04 | C105: SC | D105: =IF(OR(LEFT(C105, 2)="SE", LEFT(C105, 2)="S4"), "C6", IF(LEFT(C105, 2)="S1", "C1", IF(OR(LEFT(C105, 2)="S2", LEFT(C105, 2)="S5"), "C3&5", IF(LEFT(C105, 2)="S3", "C4", IF(LEFT(C105, 2)="SC", "C7", IF(LEFT(C105, 2)="S6", "C2", "Other")))))) -> C7 | E105: 1 | F105: QuickAccManager.sol | G105: native | H105: QuickAccManager Smart Contract signature verification can be exploited | I105: https://code4rena.com/reports/2021-10-ambire#h-04-quickaccmanager-smart-contract-signature-verification-can-be-exploited
A106: 39 | B106: H-02 | C106: S6-4 | D106: =IF(OR(LEFT(C106, 2)="SE", LEFT(C106, 2)="S4"), "C6", IF(LEFT(C106, 2)="S1", "C1", IF(OR(LEFT(C106, 2)="S2", LEFT(C106, 2)="S5"), "C3&5", IF(LEFT(C106, 2)="S3", "C4", IF(LEFT(C106, 2)="SC", "C7", IF(LEFT(C106, 2)="S6", "C2", "Other")))))) -> C2 | E106: 2 | F106: Swivel.sol | G106: compact | H106: Swivel: Taker is charged fees twice in exitVaultFillingVaultInitiate | I106: https://code4rena.com/reports/2021-09-swivel#h-02-swivel-taker-is-charged-fees-twice-in-exitvaultfillingvaultinitiate
A107: 39 | B107: H-03 | C107: SE-4 | D107: =IF(OR(LEFT(C107, 2)="SE", LEFT(C107, 2)="S4"), "C6", IF(LEFT(C107, 2)="S1", "C1", IF(OR(LEFT(C107, 2)="S2", LEFT(C107, 2)="S5"), "C3&5", IF(LEFT(C107, 2)="S3", "C4", IF(LEFT(C107, 2)="SC", "C7", IF(LEFT(C107, 2)="S6", "C2", "Other")))))) -> C6 | E107: 1 | F107: VaultTracker.sol | G107: native | H107: transferNotionalFrom doesn’t check from != to | I107: https://code4rena.com/reports/2021-09-swivel#h-03-transfernotionalfrom-doesnt-check-from--to
A108: 41 | B108: H-01 | C108: SC | D108: =IF(OR(LEFT(C108, 2)="SE", LEFT(C108, 2)="S4"), "C6", IF(LEFT(C108, 2)="S1", "C1", IF(OR(LEFT(C108, 2)="S2", LEFT(C108, 2)="S5"), "C3&5", IF(LEFT(C108, 2)="S3", "C4", IF(LEFT(C108, 2)="SC", "C7", IF(LEFT(C108, 2)="S6", "C2", "Other")))))) -> C7 | E108: 1 | F108: Auction.sol Basket.sol | G108: native | H108: Bonding mechanism allows malicious user to DOS auctions | I108: https://code4rena.com/reports/2021-10-defiprotocol#h-01-bonding-mechanism-allows-malicious-user-to-dos-auctions
A109: 42 | B109: H-01 | C109: S6-3 | D109: =IF(OR(LEFT(C109, 2)="SE", LEFT(C109, 2)="S4"), "C6", IF(LEFT(C109, 2)="S1", "C1", IF(OR(LEFT(C109, 2)="S2", LEFT(C109, 2)="S5"), "C3&5", IF(LEFT(C109, 2)="S3", "C4", IF(LEFT(C109, 2)="SC", "C7", IF(LEFT(C109, 2)="S6", "C2", "Other")))))) -> C2 | E109: 2 | F109: MochiVault.sol | G109: native | H109: Vault fails to track debt correctly that leads to bad debt | I109: https://code4rena.com/reports/2021-10-mochi#h-01-vault-fails-to-track-debt-correctly-that-leads-to-bad-debt
A110: 42 | B110: H-02 | C110: SC | D110: =IF(OR(LEFT(C110, 2)="SE", LEFT(C110, 2)="S4"), "C6", IF(LEFT(C110, 2)="S1", "C1", IF(OR(LEFT(C110, 2)="S2", LEFT(C110, 2)="S5"), "C3&5", IF(LEFT(C110, 2)="S3", "C4", IF(LEFT(C110, 2)="SC", "C7", IF(LEFT(C110, 2)="S6", "C2", "Other")))))) -> C7 | E110: 1 | F110: FeePoolV0.sol | G110: native | H110: FeePoolV0.sol#distributeMochi() will unexpectedly flush treasuryShare, causing the protocol fee cannot be properly accounted for and collected | I110: https://code4rena.com/reports/2021-10-mochi#h-02-feepoolv0soldistributemochi-will-unexpectedly-flush-treasuryshare-causing-the-protocol-fee-cannot-be-properly-accounted-for-and-collected
A111: 42 | B111: H-04 | C111: S2-1 | D111: =IF(OR(LEFT(C111, 2)="SE", LEFT(C111, 2)="S4"), "C6", IF(LEFT(C111, 2)="S1", "C1", IF(OR(LEFT(C111, 2)="S2", LEFT(C111, 2)="S5"), "C3&5", IF(LEFT(C111, 2)="S3", "C4", IF(LEFT(C111, 2)="SC", "C7", IF(LEFT(C111, 2)="S6", "C2", "Other")))))) -> C3&5 | E111: 3 | F111: MochiProfileV0.sol | G111: native | H111: registerAsset() can overwrite _assetClass value | I111: https://code4rena.com/reports/2021-10-mochi#h-04-registerasset-can-overwrite-_assetclass-value
A112: 42 | B112: H-05 | C112: S6-4 | D112: =IF(OR(LEFT(C112, 2)="SE", LEFT(C112, 2)="S4"), "C6", IF(LEFT(C112, 2)="S1", "C1", IF(OR(LEFT(C112, 2)="S2", LEFT(C112, 2)="S5"), "C3&5", IF(LEFT(C112, 2)="S3", "C4", IF(LEFT(C112, 2)="SC", "C7", IF(LEFT(C112, 2)="S6", "C2", "Other")))))) -> C2 | E112: 1 | F112: MochiVault.sol | G112: native | H112: debts calculation is not accurate | I112: https://code4rena.com/reports/2021-10-mochi#h-05-debts-calculation-is-not-accurate
... A167: 54 | B167: H-04 | C167: S3-1 | D167: =IF(OR(LEFT(C167, 2)="SE", LEFT(C167, 2)="S4"), "C6", IF(LEFT(C167, 2)="S1", "C1", IF(OR(LEFT(C167, 2)="S2", LEFT(C167, 2)="S5"), "C3&5", IF(LEFT(C167, 2)="S3", "C4", IF(LEFT(C167, 2)="SC", "C7", IF(LEFT(C167, 2)="S6", "C2", "Other")))))) -> C4 | E167: 1 | F167: MixinKeys.sol | G167: native | H167: Approvals not cleared after key transfer | I167: https://code4rena.com/reports/2021-11-unlock#h-04-approvals-not-cleared-after-key-transfer
A168: 55 | B168: H-01 | C168: S5-3 | D168: =IF(OR(LEFT(C168, 2)="SE", LEFT(C168, 2)="S4"), "C6", IF(LEFT(C168, 2)="S1", "C1", IF(OR(LEFT(C168, 2)="S2", LEFT(C168, 2)="S5"), "C3&5", IF(LEFT(C168, 2)="S3", "C4", IF(LEFT(C168, 2)="SC", "C7", IF(LEFT(C168, 2)="S6", "C2", "Other")))))) -> C3&5 | E168: 1 | F168: MapleLoan.sol | G168: =#N/A -> #N/A | H168: makePayment() Lack of access control allows malicious lender to retrieve a large portion of the funds earlier, making the borrower suffer fund loss | I168: https://code4rena.com/reports/2021-12-maple#h-01-makepayment-lack-of-access-control-allows-malicious-lender-to-retrieve-a-large-portion-of-the-funds-earlier-making-the-borrower-suffer-fund-loss
A169: 56 | B169: H-02 | C169: S6-4 | D169: =IF(OR(LEFT(C169, 2)="SE", LEFT(C169, 2)="S4"), "C6", IF(LEFT(C169, 2)="S1", "C1", IF(OR(LEFT(C169, 2)="S2", LEFT(C169, 2)="S5"), "C3&5", IF(LEFT(C169, 2)="S3", "C4", IF(LEFT(C169, 2)="SC", "C7", IF(LEFT(C169, 2)="S6", "C2", "Other")))))) -> C2 | E169: 1 | F169: CDP.sol | G169: native | H169: CDP.sol update overwrites user’s credit on every positive increment | I169: https://code4rena.com/reports/2021-11-yaxis#h-02-cdpsol-update-overwrites-users-credit-on-every-positive-increment
A170: 58 | B170: H-02 | C170: S6-4 | D170: =IF(OR(LEFT(C170, 2)="SE", LEFT(C170, 2)="S4"), "C6", IF(LEFT(C170, 2)="S1", "C1", IF(OR(LEFT(C170, 2)="S2", LEFT(C170, 2)="S5"), "C3&5", IF(LEFT(C170, 2)="S3", "C4", IF(LEFT(C170, 2)="SC", "C7", IF(LEFT(C170, 2)="S6", "C2", "Other")))))) -> C2 | E170: 1 | F170: LpIssuer.sol | G170: native | H170: Wrong implementation of performanceFee can cause users to lose 50% to 100% of their funds | I170: https://code4rena.com/reports/2021-12-mellow#h-02-wrong-implementation-of-performancefee-can-cause-users-to-lose-50-to-100-of-their-funds
A171: 58 | B171: H-03 | C171: S4-1 | D171: =IF(OR(LEFT(C171, 2)="SE", LEFT(C171, 2)="S4"), "C6", IF(LEFT(C171, 2)="S1", "C1", IF(OR(LEFT(C171, 2)="S2", LEFT(C171, 2)="S5"), "C3&5", IF(LEFT(C171, 2)="S3", "C4", IF(LEFT(C171, 2)="SC", "C7", IF(LEFT(C171, 2)="S6", "C2", "Other")))))) -> C6 | E171: 1 | F171: UniV3Vault.sol | G171: native | H171: UniV3Vault.sol#collectEarnings() can be front run | I171: https://code4rena.com/reports/2021-12-mellow#h-03-univ3vaultsolcollectearnings-can-be-front-run
A172: 58 | B172: H-04 | C172: S3-1 | D172: =IF(OR(LEFT(C172, 2)="SE", LEFT(C172, 2)="S4"), "C6", IF(LEFT(C172, 2)="S1", "C1", IF(OR(LEFT(C172, 2)="S2", LEFT(C172, 2)="S5"), "C3&5", IF(LEFT(C172, 2)="S3", "C4", IF(LEFT(C172, 2)="SC", "C7", IF(LEFT(C172, 2)="S6", "C2", "Other")))))) -> C4 | E172: 2 | F172: AaveVault.sol | G172: native | H172: AaveVault does not update TVL on deposit/withdraw | I172: https://code4rena.com/reports/2021-12-mellow#h-04-aavevault-does-not-update-tvl-on-depositwithdraw
A173: 59 | B173: H-02 | C173: SC | D173: =IF(OR(LEFT(C173, 2)="SE", LEFT(C173, 2)="S4"), "C6", IF(LEFT(C173, 2)="S1", "C1", IF(OR(LEFT(C173, 2)="S2", LEFT(C173, 2)="S5"), "C3&5", IF(LEFT(C173, 2)="S3", "C4", IF(LEFT(C173, 2)="SC", "C7", IF(LEFT(C173, 2)="S6", "C2", "Other")))))) -> C7 | E173: 1 | F173: UniswapHandler.sol PoolTransferVerification.sol | G173: native | H173: Unable to remove liquidity in Recovery Mode | I173: https://code4rena.com/reports/2021-11-malt#h-02-unable-to-remove-liquidity-in-recovery-mode
A174: 59 | B174: H-04 | C174: S6-4 | D174: =IF(OR(LEFT(C174, 2)="SE", LEFT(C174, 2)="S4"), "C6", IF(LEFT(C174, 2)="S1", "C1", IF(OR(LEFT(C174, 2)="S2", LEFT(C174, 2)="S5"), "C3&5", IF(LEFT(C174, 2)="S3", "C4", IF(LEFT(C174, 2)="SC", "C7", IF(LEFT(C174, 2)="S6", "C2", "Other")))))) -> C2 | E174: 1 | F174: AuctionBurnReserveSkew.sol | G174: native | H174: AuctionBurnReserveSkew.getPegDeltaFrequency() Wrong implementation can result in an improper amount of excess Liquidity Extension balance to be used at the end of an auction | I174: https://code4rena.com/reports/2021-11-malt#h-04-auctionburnreserveskewgetpegdeltafrequency-wrong-implementation-can-result-in-an-improper-amount-of-excess-liquidity-extension-balance-to-be-used-at-the-end-of-an-auction-
A175: 59 | B175: H-05 | C175: S6-4 | D175: =IF(OR(LEFT(C175, 2)="SE", LEFT(C175, 2)="S4"), "C6", IF(LEFT(C175, 2)="S1", "C1", IF(OR(LEFT(C175, 2)="S2", LEFT(C175, 2)="S5"), "C3&5", IF(LEFT(C175, 2)="S3", "C4", IF(LEFT(C175, 2)="SC", "C7", IF(LEFT(C175, 2)="S6", "C2", "Other")))))) -> C2 | E175: 1 | F175: AuctionEscapeHatch.sol | G175: native | H175: AuctionEschapeHatch.sol#exitEarly updates state of the auction wrongly | I175: https://code4rena.com/reports/2021-11-malt#h-05-auctioneschapehatchsolexitearly-updates-state-of-the-auction-wrongly
A176: 60 | B176: H-01 | C176: S6-4 | D176: =IF(OR(LEFT(C176, 2)="SE", LEFT(C176, 2)="S4"), "C6", IF(LEFT(C176, 2)="S1", "C1", IF(OR(LEFT(C176, 2)="S2", LEFT(C176, 2)="S5"), "C3&5", IF(LEFT(C176, 2)="S3", "C4", IF(LEFT(C176, 2)="SC", "C7", IF(LEFT(C176, 2)="S6", "C2", "Other")))))) -> C2 | E176: 1 | F176: OptimisticLedger.sol | G176: native | H176: Wrong shortfall calculation | I176: https://code4rena.com/reports/2021-12-perennial#h-01-wrong-shortfall-calculation
A177: 60 | B177: H-02 | C177: SC | D177: =IF(OR(LEFT(C177, 2)="SE", LEFT(C177, 2)="S4"), "C6", IF(LEFT(C177, 2)="S1", "C1", IF(OR(LEFT(C177, 2)="S2", LEFT(C177, 2)="S5"), "C3&5", IF(LEFT(C177, 2)="S3", "C4", IF(LEFT(C177, 2)="SC", "C7", IF(LEFT(C177, 2)="S6", "C2", "Other")))))) -> C7 | E177: 1 | F177: Collateral.sol | G177: native | H177: withdrawTo Does Not Sync Before Checking A Position’s Margin Requirements | I177: https://code4rena.com/reports/2021-12-perennial#h-02-withdrawto-does-not-sync-before-checking-a-positions-margin-requirements
A178: 61 | B178: H-01 | C178: S6-4 | D178: =IF(OR(LEFT(C178, 2)="SE", LEFT(C178, 2)="S4"), "C6", IF(LEFT(C178, 2)="S1", "C1", IF(OR(LEFT(C178, 2)="S2", LEFT(C178, 2)="S5"), "C3&5", IF(LEFT(C178, 2)="S3", "C4", IF(LEFT(C178, 2)="SC", "C7", IF(LEFT(C178, 2)="S6", "C2", "Other")))))) -> C2 | E178: 1 | F178: CreditLine.sol | G178: too long | H178: In CreditLine#_borrowTokensToLiquidate, oracle is used wrong way | I178: https://code4rena.com/reports/2021-12-sublime#h-01-in-creditline_borrowtokenstoliquidate-oracle-is-used-wrong-way
A179: 61 | B179: H-02 | C179: S6-2 | D179: =IF(OR(LEFT(C179, 2)="SE", LEFT(C179, 2)="S4"), "C6", IF(LEFT(C179, 2)="S1", "C1", IF(OR(LEFT(C179, 2)="S2", LEFT(C179, 2)="S5"), "C3&5", IF(LEFT(C179, 2)="S3", "C4", IF(LEFT(C179, 2)="SC", "C7", IF(LEFT(C179, 2)="S6", "C2", "Other")))))) -> C2 | E179: 1 | F179: SavingsAccountUtil.sol | G179: native | H179: Wrong returns of SavingsAccountUtil.depositFromSavingsAccount() can cause fund loss | I179: https://code4rena.com/reports/2021-12-sublime#h-02-wrong-returns-of-savingsaccountutildepositfromsavingsaccount-can-cause-fund-loss
...

Sheet stkbar
B1: C1 | C1: C2 | D1: C3&5 | E1: C4 | F1: C6 | G1: C7 | H1: Total
A2: Code4rena | B2: 24 | C2: 63 | D2: 34 | E2: 21 | F2: 46 | G2: 58 | H2: =SUM(B2:G2) -> 246
A3: uniq | B3: 63 | C3: 148 | D3: 76 | E3: 46 | F3: 192 | G3: 105 | H3: =SUM(B3:G3) -> 630
A4: TP | B4: 26 | C4: 67 | D4: 60 | E4: 22 | F4: 116 | G4: 76 | H4: =SUM(B4:G4) -> 367
A5: report | B5: 13 | C5: 12 | D5: 16 | E5: 9 | F5: 11 | G5: 7 | H5: =SUM(B5:G5) -> 68
A6: high | B6: 8 | C6: 5 | D6: 9 | E6: 7 | F6: 5 | G6: 2 | H6: =SUM(B6:G6) -> 36
A7: high% | B7: =B6/B2 -> 0.33333333 | C7: =C6/C2 -> 0.079365079 | D7: =D6/D2 -> 0.26470588 | E7: =E6/E2 -> 0.33333333 | F7: =F6/F2 -> 0.10869565 | G7: =G6/G2 -> 0.034482759 | H7: =H6/H2 -> 0.14634146
C14: high in report | D14: non-high in report | E14: true not in report | F14: false alarm | G14: total
A15: C1
B16: Code4rena | C16: 24 | G16: =SUM(C16:F16) -> 24
B17: GPT_alarms | C17: 8 | D17: =B5-C17 -> 5 | E17: =B4-B5 -> 13 | F17: =B3-B4 -> 37 | G17: =SUM(C17:F17) -> 63
A19: C2
B20: Code4rena | C20: 63 | G20: =SUM(C20:F20) -> 63
B21: GPT_alarms | C21: 5 | D21: =C5-C21 -> 7 | E21: =C4-C5 -> 55 | F21: =C3-C4 -> 81 | G21: =SUM(C21:F21) -> 148
A23: C3&5
B24: Code4rena | C24: 34 | G24: =SUM(C24:F24) -> 34
B25: GPT_alarms | C25: 9 | D25: =D5-C25 -> 7 | E25: =D4-D5 -> 44 | F25: =D3-D4 -> 16 | G25: =SUM(C25:F25) -> 76
A27: C4
B28: Code4rena | C28: 21 | G28: =SUM(C28:F28) -> 21
B29: GPT_alarms | C29: 7 | D29: =E5-C29 -> 2 | E29: =E4-E5 -> 13 | F29: =E3-E4 -> 24 | G29: =SUM(C29:F29) -> 46
A31: C6
B32: Code4rena | C32: 46 | G32: =SUM(C32:F32) -> 46
B33: GPT_alarms | C33: 5 | D33: =F5-C33 -> 6 | E33: =F4-F5 -> 105 | F33: =F3-F4 -> 76 | G33: =SUM(C33:F33) -> 192
A35: C7
B36: Code4rena | C36: 58 | G36: =SUM(C36:F36) -> 58
B37: GPT_alarms | C37: 2 | D37: =G5-C37 -> 5 | E37: =G4-G5 -> 69 | F37: =G3-G4 -> 29 | G37: =SUM(C37:F37) -> 105
A39: placeholder

Sheet c1raw
A1: OriProj | B1: Proj | C1: Test | D1: Seq | E1: Functions | F1: Explanation
A2: 3_1 | B2: 3 | C2: 1 | D2: 1 | E2: getPriceFromAMM | F2: In this smart contract, the getPriceFromAMM function is responsible for fetching the price of a token from the AMM (Automated Market Maker). While the contract does have some mechanisms in place to prevent price manipulation, the getPriceFromAMM function can still be susceptible to manipulation. The reason being that it relies on the external data provided by the AMM, which can be subject to manipulation through methods like sandwich attacks or flash loans. An attacker could temporarily manipulate the prices on the AMM and influence the token prices fetched by the getPriceFromAMM function.
A3: 3_1 | B3: 3 | C3: 1 | D3: 2 | E3: getCurrentPriceInPeg | F3: The getCurrentPriceInPeg function is responsible for determining the current price of a token in the peg. This function relies on the prices fetched by the getPriceFromAMM function, which, as mentioned earlier, can be manipulated. Therefore, any manipulation in getPriceFromAMM can also affect the getCurrentPriceInPeg function. This can potentially lead to incorrect price estimations and impact the entire smart contract's functionality.
A4: 3_2 | B4: 3 | C4: 2 | D4: 1 | E4: getPriceFromAMM | F4: The getPriceFromAMM function fetches the price of a token from an external AMM (Automated Market Maker) and updates the stored price of the token. The prices fetched from external AMMs can be manipulated if a malicious actor has a substantial influence on the liquidity of the token. This could lead to incorrect price updates, affecting the smart contract's behavior.
A5: 3_2 | B5: 3 | C5: 2 | D5: 2 | E5: getCurrentPriceInPeg | F5: The getCurrentPriceInPeg function retrieves the current price of the token in the pegged currency. The price is fetched by calling the getPriceFromAMM function, which is susceptible to price manipulation as explained above. If the price of the token is manipulated in the AMM, it will affect the price returned by this function as well.
A6: 3_2 | B6: 3 | C6: 2 | D6: 3 | E6: viewCurrentPriceInPeg | F6: The viewCurrentPriceInPeg function is a view function that returns the current price of a token in the pegged currency. It calculates the price by using data fetched from external AMMs through UniswapStyleLib.getAmountsOut, which can be manipulated if a malicious actor has a significant influence on the liquidity of the token. This can lead to incorrect price estimations, impacting the contract's behavior.
A7: 3_3 | B7: 3 | C7: 3 | D7: 1 | E7: getPriceFromAMM | F7: The function getPriceFromAMM retrieves the price from the AMM, but it has some potential for price manipulation. The contract checks if the output amount is within a predefined range (UPDATE_MIN_PEG_AMOUNT and UPDATE_MAX_PEG_AMOUNT) before updating the token price. An attacker could manipulate the price in the AMM by placing large orders to force the output amount outside of the predefined range, causing the contract to not update the price. This manipulation could lead to incorrect pricing data being used in the smart contract.
A8: 3_3 | B8: 3 | C8: 3 | D8: 2 | E8: setLiquidationPath | F8: The function setLiquidationPath sets the liquidation path from a given token to the current liquidation peg. The path and tokens are provided externally and not verified within the contract, which may leave the contract vulnerable to price manipulation. An attacker could provide a custom path that includes a manipulated token price in the AMM or even a malicious AMM contract. This could lead to incorrect pricing data being used in the smart contract, impacting the liquidation process and other contract functions that rely on accurate pricing information.
A9: 16_1 | B9: 16 | C9: 1 | D9: 1 | E9: recordTrade | F9: The function 'recordTrade' updates pricing information and uses the external oracle's latest answer through 'uint256 currentOraclePrice = oracle.latestAnswer();'. This exposes the contract to potential price oracle manipulation. An attacker could manipulate the oracle's data, thus influencing the pricing information in the smart contract, which could lead to incorrect funding rates and other consequences.
A10: 16_1 | B10: 16 | C10: 1 | D10: 2 | E10: fairPrice | F10: The 'fairPrice' function returns the fair price by using the external oracle's latest answer through 'oracle.latestAnswer()'. This exposes the contract to potential price oracle manipulation. An attacker could manipulate the oracle's data, which would lead to an incorrect fair price being returned, possibly affecting the decision-making process of the smart contract's users.
A11: 16_2 | B11: 16 | C11: 2 | D11: 1 | E11: recordTrade | F11: In the `recordTrade` function, the `tradePrice` is used to update the hourly tracer prices. Since the `tradePrice` is not directly fetched from the oracle but passed as a function argument, it may be manipulated by an attacker to influence the hourly prices.
A12: 16_2 | B12: 16 | C12: 2 | D12: 2 | E12: updatePrice | F12: The `updatePrice` function is called in the `recordTrade` function, and it also takes `marketPrice` and `oraclePrice` as input arguments. Since these arguments are passed down from the `recordTrade` function, they might be manipulated by an attacker to influence the hourly prices and eventually affect the funding rate and time value.
A13: 16_2 | B13: 16 | C13: 2 | D13: 3 | E13: fairPrice | F13: The `fairPrice` function directly uses the `oracle.latestAnswer()` to calculate the fair price. If an attacker can manipulate the oracle's latest answer, it can result in an incorrect fair price. This can be mitigated by using a secure oracle implementation, but it's crucial to be aware of the possibility of oracle manipulation affecting the smart contract.
... A134: 193_3 | B134: 193 | C134: 3 | D134: 1 | E134: price | F134: The price function calculates the price of the fractional tokens based on the reserves of the base token and the fractional tokens. It is defined as: (_baseTokenReserves() * ONE) / fractionalTokenReserves(). Since the contract allows users to add and remove liquidity, buy, and sell tokens, they can influence the reserves of the base and fractional tokens. Consequently, users can manipulate the price by influencing the reserves through these functions.

Sheet c1Uniq
A1: Proj | B1: Functions | C1: Certainty | D1: comments | E1: Note | F1: Link | G1: GPT Expla
A2: 3 | B2: getPriceFromAMM | C2: =COUNTIFS(c1raw!B:B, A2, c1raw!$E:$E, B2) -> 3 | D2: M-08 | E2: low risk | F2: https://code4rena.com/reports/2021-04-marginswap/#m-08-priceaware-uses-prices-from-getamountsout | G2: In this smart contract, the getPriceFromAMM function is responsible for fetching the price of a token from the AMM (Automated Market Maker). While the contract does have some mechanisms in place to prevent price manipulation, the getPriceFromAMM function can still be susceptible to manipulation. The reason being that it relies on the external data provided by the AMM, which can be subject to manipulation through methods like sandwich attacks or flash loans. An attacker could temporarily manipulate the prices on the AMM and influence the token prices fetched by the getPriceFromAMM function.
A3: 3 | B3: getCurrentPriceInPeg | C3: =COUNTIFS(c1raw!B:B, A3, c1raw!$E:$E, B3) -> 2 | D3: H-03 | E3: high risk | F3: https://code4rena.com/reports/2021-04-marginswap/#h-03-price-feed-can-be-manipulated | G3: The getCurrentPriceInPeg function is responsible for determining the current price of a token in the peg. This function relies on the prices fetched by the getPriceFromAMM function, which, as mentioned earlier, can be manipulated. Therefore, any manipulation in getPriceFromAMM can also affect the getCurrentPriceInPeg function. This can potentially lead to incorrect price estimations and impact the entire smart contract's functionality.
A4: 3 | B4: setLiquidationPath | C4: =COUNTIFS(c1raw!B:B, A4, c1raw!$E:$E, B4) -> 1 | D4: M-02 | E4: low risk | F4: https://code4rena.com/reports/2021-04-marginswap/#m-02-missing-checks-if-pairs-equal-tokens | G4: The function setLiquidationPath sets the liquidation path from a given token to the current liquidation peg. The path and tokens are provided externally and not verified within the contract, which may leave the contract vulnerable to price manipulation. An attacker could provide a custom path that includes a manipulated token price in the AMM or even a malicious AMM contract. This could lead to incorrect pricing data being used in the smart contract, impacting the liquidation process and other contract functions that rely on accurate pricing information.
A5: 3 | B5: viewCurrentPriceInPeg | C5: =COUNTIFS(c1raw!B:B, A5, c1raw!$E:$E, B5) -> 1 | D5: =TRUE() -> 1 | E5: very low risk | F5: external data | G5: The viewCurrentPriceInPeg function is a view function that returns the current price of a token in the pegged currency. It calculates the price by using data fetched from external AMMs through UniswapStyleLib.getAmountsOut, which can be manipulated if a malicious actor has a significant influence on the liquidity of the token. This can lead to incorrect price estimations, impacting the contract's behavior.
A6: 16 | B6: recordTrade | C6: =COUNTIFS(c1raw!B:B, A6, c1raw!$E:$E, B6) -> 3 | D6: H-01 | E6: high risk | F6: https://code4rena.com/reports/2021-06-tracer/#h-01-wrong-trading-pricing-calculations | G6: The function 'recordTrade' updates pricing information and uses the external oracle's latest answer through 'uint256 currentOraclePrice = oracle.latestAnswer();'. This exposes the contract to potential price oracle manipulation. An attacker could manipulate the oracle's data, thus influencing the pricing information in the smart contract, which could lead to incorrect funding rates and other consequences.
A7: 16 | B7: fairPrice | C7: =COUNTIFS(c1raw!B:B, A7, c1raw!$E:$E, B7) -> 2 | D7: H-01 | E7: high risk, affected by above | F7: https://code4rena.com/reports/2021-06-tracer/#h-02-wrong-trading-pricing-calculations | G7: The 'fairPrice' function returns the fair price by using the external oracle's latest answer through 'oracle.latestAnswer()'. This exposes the contract to potential price oracle manipulation. An attacker could manipulate the oracle's data, which would lead to an incorrect fair price being returned, possibly affecting the decision-making process of the smart contract's users.
A8: 16 | B8: updatePrice | C8: =COUNTIFS(c1raw!B:B, A8, c1raw!$E:$E, B8) -> 1 | D8: H-01 | E8: high risk, affected by above | F8: https://code4rena.com/reports/2021-06-tracer/#h-03-wrong-trading-pricing-calculations | G8: The `updatePrice` function is called in the `recordTrade` function, and it also takes `marketPrice` and `oraclePrice` as input arguments. Since these arguments are passed down from the `recordTrade` function, they might be manipulated by an attacker to influence the hourly prices and eventually affect the funding rate and time value.
A9: 16 | B9: get24HourPrices | C9: =COUNTIFS(c1raw!B:B, A9, c1raw!$E:$E, B9) -> 1 | D9: H-01 | E9: high risk, affected by above | F9: https://code4rena.com/reports/2021-06-tracer/#h-02-wrong-trading-pricing-calculations | G9: The `get24HourPrices` function calculates the average 24-hour price for both the tracer and oracle prices. If an attacker is able to manipulate the input prices in the `recordTrade` and `updatePrice` functions, they can influence the 24-hour average prices returned by this function. This would eventually impact the time value calculation and other functions that rely on the 24-hour average prices.
A10: 16 | B10: getHourlyAvgTracerPrice | C10: =COUNTIFS(c1raw!B:B, A10, c1raw!$E:$E, B10) -> 1 | D10: H-01 | E10: high risk, affected by above | F10: https://code4rena.com/reports/2021-06-tracer/#h-02-wrong-trading-pricing-calculations | G10: The `getHourlyAvgTracerPrice` function calculates the hourly average price for a given tracer market. Since this function relies on the hourly tracer prices, which can be manipulated through the `recordTrade` and `updatePrice` functions, an attacker could influence the hourly average price for a tracer market.
A11: 16 | B11: getHourlyAvgOraclePrice | C11: =COUNTIFS(c1raw!B:B, A11, c1raw!$E:$E, B11) -> 1 | D11: H-01 | E11: high risk, affected by above | F11: https://code4rena.com/reports/2021-06-tracer/#h-02-wrong-trading-pricing-calculations | G11: The `getHourlyAvgOraclePrice` function calculates the hourly average price for a given oracle market. This function relies on the hourly oracle prices, which can be manipulated through the `recordTrade` and `updatePrice` functions. An attacker could influence the hourly average price for an oracle market, affecting the overall price calculation and funding rates.
A12: 20 | B12: mintSynth | C12: =COUNTIFS(c1raw!B:B, A12, c1raw!$E:$E, B12) -> 3 | D12: H-09 | E12: high risk | F12: https://code4rena.com/reports/2021-07-spartan/#h-09-arbitrary-synth-mintburn-from-pool | G12: The mintSynth function allows a pool to mint new synthetic tokens based on the amount of LP tokens added. However, there is no validation on the price oracles used to determine the value of the underlying assets. An attacker could manipulate the oracle to create an inaccurate price, allowing them to mint more synthetic tokens than they should be able to. This would result in an imbalanced pool and potential losses for other participants.
A13: 20 | B13: realise | C13: =COUNTIFS(c1raw!B:B, A13, c1raw!$E:$E, B13) -> 3 | D13: H-05 | E13: high risk | F13: https://code4rena.com/reports/2021-07-spartan/#h-05-synth-realise-is-vulnerable-to-flash-loan-attacks | G13: The realise function is designed to burn excess LP tokens when their value outweighs the value of the synthetic token supply. The function relies on external price data to calculate the value of LP tokens and synthetic tokens. If an attacker manipulates the oracle, they could cause the function to burn more or less LP tokens than necessary, leading to imbalances in the pool and potential losses for other participants.
A14: 20 | B14: harvestSingle | C14: =COUNTIFS(c1raw!B:B, A14, c1raw!$E:$E, B14) -> 3 | D14: M-08 | E14: low risk | F14: https://code4rena.com/reports/2021-07-spartan/#m-08-synthvault-deposit-lockup-bypass | G14: The smart contract fetches external data such as prices through the iUTILS contract. The iUTILS contract calculates prices based on the liquidity pools in the DAO, which are external to the SynthVault contract. The calcCurrentReward and calcReward functions, which are used by the harvestSingle function, rely on these external prices to calculate rewards for the user. If an attacker can manipulate the prices in the liquidity pools, they could potentially manipulate the rewards distribution, causing incorrect reward payouts. This could lead to the exploitation of the SynthVault contract and have an impact on the price of various tokens in the system.
A15: 20 | B15: calcSpotValueInBaseWithPool | C15: =COUNTIFS(c1raw!B:B, A15, c1raw!$E:$E, B15) -> 3 | D15: =TRUE() -> 1 | E15: very low risk | F15: external data | G15: The function calcSpotValueInBaseWithPool calculates the value of an amount in the base token, given a pool. However, it relies on data fetched from external contracts (iPOOL(pool).baseAmount() and iPOOL(pool).tokenAmount()), which can be manipulated by malicious actors, potentially impacting the calculated spot value in the base token.
A16: 20 | B16: calcSpotValueInTokenWithPool | C16: =COUNTIFS(c1raw!B:B, A16, c1raw!$E:$E, B16) -> 3 | D16: =TRUE() -> 1 | E16: very low risk | F16: external data | G16: Similar to calcSpotValueInBaseWithPool, calcSpotValueInTokenWithPool calculates the value of an amount in a token given a pool, and it also relies on the same external data (iPOOL(pool).baseAmount() and iPOOL(pool).tokenAmount()). As a result, this function is also susceptible to price manipulation.
A17: 20 | B17: burnSynth | C17: =COUNTIFS(c1raw!B:B, A17, c1raw!$E:$E, B17) -> 2 | D17: L-11 | E17: low risk | F17: https://code4rena.com/reports/2021-07-spartan/#l-11-inconsistent-value-of-burnsynth-between-pool-and-synth | G17: The burnSynth function allows users to burn synthetic tokens and receive LP tokens in return. Similar to mintSynth, the function relies on external price data to calculate the amount of LP tokens to return. If an attacker manipulates the oracle to provide an inaccurate price, they could receive more LP tokens than they should, causing an imbalance in the pool and potential losses for other participants.
A18: 20 | B18: swapTo | C18: =COUNTIFS(c1raw!B:B, A18, c1raw!$E:$E, B18) -> 2 | D18: =TRUE() -> 1 | E18: very low risk | F18: external data | G18: The 'swapTo' function allows swapping of tokens in the contract. The external data is fetched from the '_DAO()' function that returns the DAO's address, which is used to fetch the pool factory. However, price oracle manipulation could potentially occur if an attacker manipulates the price of the tokens in the pool, leading to an incorrect valuation of the tokens being swapped, causing potential losses for the users interacting with the smart contract. This is also applicable to other functions that use '_DAO()' to fetch pool-related information such as 'addLiquidity', 'zapLiquidity', 'removeLiquidity', etc.
A19: 20 | B19: swapAssetToSynth | C19: =COUNTIFS(c1raw!B:B, A19, c1raw!$E:$E, B19) -> 2 | D19: =TRUE() -> 1 | E19: very low risk | F19: external data | G19: The 'swapAssetToSynth' function allows swapping of assets to synthetic assets. It fetches data from the '_DAO()' function to obtain the pool factory and eventually the pool. Price oracle manipulation could occur if the price of the synthetic asset is manipulated, leading to an incorrect valuation of the synthetic asset being minted, causing potential losses for the users interacting with the smart contract.
A20: 20 | B20: swapSynthToAsset | C20: =COUNTIFS(c1raw!B:B, A20, c1raw!$E:$E, B20) -> 2 | D20: =TRUE() -> 1 | E20: very low risk | F20: external data | G20: The 'swapSynthToAsset' function allows swapping of synthetic assets to other assets. It fetches data from the '_DAO()' function to obtain the pool factory and eventually the pool. Price oracle manipulation could occur if the price of the synthetic asset is manipulated, leading to an incorrect valuation of the synthetic asset being burned, causing potential losses for the users interacting with the smart contract.
A21: 20 | B21: calcSwapValueInBaseWithPool | C21: =COUNTIFS(c1raw!B:B, A21, c1raw!$E:$E, B21) -> 2 | D21: =TRUE() -> 1 | E21: very low risk | F21: external data | G21: The function calcSwapValueInBaseWithPool calculates the value of an amount after a swap in the base token, given a pool. This function uses external data fetched from iPOOL(pool).baseAmount() and iPOOL(pool).tokenAmount(). Since these external data points can be manipulated, this function is vulnerable to price manipulation.
A22: 20 | B22: calcSwapValueInTokenWithPool | C22: =COUNTIFS(c1raw!B:B, A22, c1raw!$E:$E, B22) -> 2 | D22: =TRUE() -> 1 | E22: very low risk | F22: external data | G22: The function calcSwapValueInTokenWithPool calculates the value of an amount after a swap in a token, given a pool. It also relies on external data from iPOOL(pool).baseAmount() and iPOOL(pool).tokenAmount(), which makes it susceptible to price manipulation if these data points are manipulated.
A23: 20 | B23: swap | C23: =COUNTIFS(c1raw!B:B, A23, c1raw!$E:$E, B23) -> 1 | D23: =TRUE() -> 1 | E23: very low risk | F23: external data | G23: In the swap function, external price data is fetched from the pool contracts. If an attacker can manipulate the price of tokens in these pools, they can create artificial arbitrage opportunities and exploit them, leading to incorrect token prices and potential losses for other users.
A24: 20 | B24: calcSwapOutput | C24: =COUNTIFS(c1raw!B:B, A24, c1raw!$E:$E, B24) -> 1 | D24: =FALSE() -> 0 | F24: public function with users' inputs | G24: The 'calcSwapOutput' function calculates the output of a swap based on the input amount, the token reserves, and the base reserves. The function uses the formula `y = (x * X * Y) / (x + X)^2`. An attacker can manipulate the oracle price by manipulating the reserves of the pool, i.e., changing the values of X and Y, which will affect the swap output.
A25: 20 | B25: calcSwapFee | C25: =COUNTIFS(c1raw!B:B, A25, c1raw!$E:$E, B25) -> 1 | D25: =FALSE() -> 0 | F25: public function with users' inputs | G25: The 'calcSwapFee' function calculates the swap fee based on the input amount, the token reserves, and the base reserves. The function uses the formula `y = (x * x * Y) / (x + X)^2`. Similar to the 'calcSwapOutput' function, an attacker can manipulate the oracle price by manipulating the reserves of the pool, i.e., changing the values of X and Y, which will affect the swap fee calculation.
A26: 20 | B26: buyTo | C26: =COUNTIFS(c1raw!B:B, A26, c1raw!$E:$E, B26) -> 1 | D26: =TRUE() -> 1 | E26: very low risk | F26: external data | G26: The 'buyTo' function allows a user to buy a token by transferring the BASE token. This function relies on the price provided by the Pool contract, which can be manipulated by an attacker through flash loans or providing large amounts of tokens in a single transaction. The manipulation of the price in the liquidity pools will affect the price used in the 'buyTo' function, leading to potential price manipulation.
A27: 20 | B27: sellTo | C27: =COUNTIFS(c1raw!B:B, A27, c1raw!$E:$E, B27) -> 1 | D27: =TRUE() -> 1 | E27: very low risk | F27: external data | G27: In the 'sellTo' function, users can sell their tokens in exchange for the BASE token. Similar to the 'buyTo' function, this function relies on the price provided by the Pool contract, which can be manipulated by an attacker. The price manipulation in the liquidity pools will impact the price used in the 'sellTo' function, leading to potential price manipulation.
A28: 23 | B28: getRiskAdjustedPresentValue | C28: =COUNTIFS(c1raw!B:B, A28, c1raw!$E:$E, B28) -> 1 | D28: =TRUE() -> 1 | E28: very low risk | F28: external data | G28: In the getRiskAdjustedPresentValue function, the oracle rate is used to calculate the present value of an fCash asset with risk adjustments. Since the oracle rate is fetched from an external source, manipulating the oracle rate would directly impact the calculated present value of an fCash asset in the smart contract, potentially affecting the overall valuation of the assets.
A29: 23 | B29: getLiquidityTokenValue | C29: =COUNTIFS(c1raw!B:B, A29, c1raw!$E:$E, B29) -> 2 | D29: H-10 | E29: high risk | F29: https://code4rena.com/reports/2021-08-notional/#h-10-liquidity-token-value-can-be-manipulated | G29: The getLiquidityTokenValue function calculates the asset cash claim and the present value of the fCash asset (if it exists) using the market oracle rate. As the market.oracleRate is fetched from an external source, price manipulation could occur if the oracle rate is manipulated. The manipulated oracle rate will affect the present value calculations for the fCash assets.
A30: 23 | B30: getNetCashGroupValue | C30: =COUNTIFS(c1raw!B:B, A30, c1raw!$E:$E, B30) -> 3 | D30: =TRUE() -> 1 | E30: very low risk | F30: external data | G30: The getNetCashGroupValue function calculates the present value of assets in the cash group using the oracle rate fetched from the cash group through the calculateOracleRate method. This external dependency on the oracle rate means that if the oracle rate is manipulated, the present value calculations for the assets in the cash group would be affected, resulting in potential price manipulation.
A31: 42 | B31: _shareMochi | C31: =COUNTIFS(c1raw!B:B, A31, c1raw!$E:$E, B31) -> 1 | D31: =TRUE() -> 1 | E31: very low risk | F31: external data | G31: {=INDEX(c1raw!$F:$F, MATCH(1, (c1raw!B:B=A31) * (c1raw!$E:$E=B31), 0))} -> In the _shareMochi function, the smart contract fetches external data from the Mochi token balance to distribute Mochi to vMochi Vault and veCRV Holders. Although there isn't a direct price oracle manipulation in this function, if the price oracle is manipulated in the _buyMochi function, it will affect the Mochi token balance and the amounts distributed in this function. This can lead to incorrect distribution of rewards and losses for the participants in the smart contract.
A32: 42 | B32: _buyCRV | C32: =COUNTIFS(c1raw!B:B, A32, c1raw!$E:$E, B32) -> 1 | D32: =TRUE() -> 1 | E32: very low risk | F32: external data | G32: {=INDEX(c1raw!$F:$F, MATCH(1, (c1raw!B:B=A32) * (c1raw!$E:$E=B32), 0))} -> In the _buyCRV function, the smart contract fetches external data from the Uniswap router to swap USDM for CRV tokens. Since Uniswap uses an automated market maker model, it is vulnerable to price manipulation attacks. An attacker can manipulate the price oracle by trading large volumes of tokens right before or after this function is called, which can lead to incorrect token prices and affect the outcome of the swap.
A33: 42 | B33: distributeMochi | C33: =COUNTIFS(c1raw!B:B, A33, c1raw!$E:$E, B33) -> 4 | D33: =TRUE() -> 1 | E33: very low risk | F33: external data | G33: The distributeMochi function is responsible for buying Mochi with the mochiShare, which is executed through the _buyMochi internal function. This process fetches price data from Uniswap by using the IUniswapV2Router02's swapExactTokensForTokens function. An attacker can manipulate the price of the Mochi token on Uniswap by executing a sandwich attack, for instance, by placing large buy and sell orders around the target transaction. This manipulation can lead to an incorrect price feed, which could result in the FeePoolV0 contract buying Mochi at an inflated or deflated price.
A34: 42 | B34: veCRVInitialize | C34: =COUNTIFS(c1raw!B:B, A34, c1raw!$E:$E, B34) -> 3 | D34: =TRUE() -> 1 | E34: very low risk | F34: external data | G34: The veCRVInitialize function calls the _buyCRV internal function to buy CRV tokens with veCRVShare. This function fetches price data from Uniswap by using the IUniswapV2Router02's swapExactTokensForTokens function. An attacker can manipulate the price of the CRV token on Uniswap by executing a sandwich attack, for instance, by placing large buy and sell orders around the target transaction. This manipulation can lead to an incorrect price feed, which could result in the MochiTreasuryV0 contract buying CRV at an inflated or deflated price.
A35: 42 | B35: veCRVlock | C35: =COUNTIFS(c1raw!B:B, A35, c1raw!$E:$E, B35) -> 3 | D35: =TRUE() -> 1 | E35: very low risk | F35: external data | G35: The veCRVlock function calls the _buyCRV internal function to buy CRV tokens with veCRVShare before locking them in the veCrv contract. The price manipulation mentioned in the first sequence can impact the amount of CRV tokens bought and subsequently locked. If the CRV token price is manipulated, the contract might lock an incorrect amount of tokens in the veCrv contract, leading to potentially unfair allocations for users participating in the system.
A36: 42 | B36: _buyMochi | C36: =COUNTIFS(c1raw!B:B, A36, c1raw!$E:$E, B36) -> 2 | D36: =TRUE() -> 1 | E36: very low risk | F36: external data | G36: The _buyMochi function is also susceptible to price oracle manipulation for the same reasons mentioned above for the distributeMochi function. It relies on the Uniswap V2 router to swap USDM tokens for Mochi tokens, which could be manipulated by an attacker through large trades on Uniswap. This would allow the attacker to obtain Mochi tokens at an artificially skewed price.
A37: 52 | B37: _swap | C37: =COUNTIFS(c1raw!B:B, A37, c1raw!$E:$E, B37) -> 5 | D37: =TRUE() -> 1 | E37: very low risk | F37: external data | G37: The _swap function can be potentially manipulated due to its reliance on external data fetched from the pool contract. The pool contract calculates the conversion rate between assets, and if the pool contract is manipulated or has incorrect pricing data, it would lead to inaccurate conversions and potential price manipulation. The manipulation could occur due to oracle attacks or front-running in the pool contract, which would have a cascading effect on the smart contract relying on that data.
A38: 52 | B38: calculateInGivenOut | C38: =COUNTIFS(c1raw!B:B, A38, c1raw!$E:$E, B38) -> 2 | D38: =TRUE() -> 1 | E38: very low risk | F38: external data | G38: In the calculateInGivenOut function, the contract fetches the pool reserves and calculates the amountIn based on the given amountOut and the reserve amounts. Since the reserve amounts are fetched from the external VaderPool contract, it is possible for an attacker to manipulate the prices in that external contract, thus affecting the prices and the output of the calculateInGivenOut function.
A39: 52 | B39: calculateOutGivenIn | C39: =COUNTIFS(c1raw!B:B, A39, c1raw!$E:$E, B39) -> 2 | D39: =TRUE() -> 1 | E39: very low risk | F39: external data | G39: In the calculateOutGivenIn function, the contract fetches the pool reserves and calculates the amountOut based on the given amountIn and the reserve amounts. Since the reserve amounts are fetched from the external VaderPool contract, it is possible for an attacker to manipulate the prices in that external contract, thus affecting the prices and the output of the calculateOutGivenIn function.
A40: 52 | B40: mintSynth | C40: =COUNTIFS(c1raw!B:B, A40, c1raw!$E:$E, B40) -> 2 | D40: H-01 | E40: high risk | F40: https://code4rena.com/reports/2021-11-vader/#h-01-minting-and-burning-synths-exposes-users-to-unlimited-slippage | G40: The mintSynth function mints synthetic assets based on the native asset amount deposited. The price for minting these synthetic assets is calculated using the current reserve values of native and foreign assets. However, there is no direct price oracle or external data fetched in this function. An attacker could manipulate the reserves or amounts deposited to influence the price of minted synthetic assets.
...

Sheet c2raw
A1: proj | B1: ID | C1: tests | D1: seq | E1: functions | F1: bug type | G1: justify | H1: notes | I1: explanation | J1: Column1
A2: 3_1 | B2: 3 | C2: 1 | D2: 1 | E2: adjustAmounts | F2: Underflow | I2: In the `adjustAmounts` function, there is a statement `account.holdings[fromToken] = account.holdings[fromToken] - soldAmount;` which can potentially cause an underflow error if `soldAmount` is greater than `account.holdings[fromToken]`. Solidity will not throw an exception on underflow or overflow. Instead, it will silently give an incorrect result.
A3: 3_1 | B3: 3 | C3: 1 | D3: 1 | E3: setLendingCap, setLendingBuffer, setHourlyYieldAPR | F3: Lack of Input Validation | I3: Without proper validation, these functions are prone to misuse or bugs resulting from extreme input values.
A4: 3_1 | B4: 3 | C4: 1 | D4: 2 | E4: applyBorrowInterest, registerBorrow, payOff | F4: Potential Overflow and Underflow | I4: These functions perform arithmetic operations without explicitly checking for overflows or underflows.
A5: 3_1 | B5: 3 | C5: 1 | D5: 3 | E5: N/A | F5: Lack of Events | I5: The contract does not emit events, making it difficult to monitor state changes.
A6: 3_1 | B6: 3 | C6: 1 | D6: 4 | E6: deactivateIssuer | F6: Inaccurate Error Messages | I6: The error message does not correctly reflect the action being performed.
A7: 3_1 | B7: 3 | C7: 1 | D7: 5 | E7: N/A | F7: Implicit Visibility in State Variables | I7: Not declaring visibility explicitly can lead to confusion about how and where state variables can be accessed.
A8: 3_2 | B8: 3 | C8: 2 | D8: 1 | E8: `_makeHourlyBond` | F8: Arithmetic Overflow/Underflow | I8: In the `_makeHourlyBond` function, the `bond.amount` and `lendingMeta[issuer].totalLending` are incremented by `amount`. In Solidity, if these variables are already at their maximum value, this addition could lead to an overflow, resetting the value to zero, which could lead to erroneous behavior. The same issue applies for underflow when subtracting `amount` in the `_withdrawHourlyBond` function.
A9: 3_2 | B9: 3 | C9: 2 | D9: 2 | E9: `updateHourlyBondAmount` | F9: Arithmetic Overflow/Underflow | I9: The same issue applies in the `updateHourlyBondAmount` function where `deltaAmount = bond.amount - oldAmount` and `lendingMeta[issuer].totalLending += deltaAmount;` could cause an overflow or underflow.
A10: 3_2 | B10: 3 | C10: 2 | D10: 3 | E10: `getUpdatedHourlyYield` | F10: Unchecked External Call | I10: The function `getUpdatedHourlyYield` involves a complex calculation and updates to various parameters. If any of these internal calls fail, it will stop the execution of the contract. This could be mitigated by using checks, effects, and interactions pattern in Solidity.
A11: 3_2 | B11: 3 | C11: 2 | D11: 4 | E11: `calcCumulativeYieldFP` | F11: Uncontrolled loop iteration | I11: In the function `calcCumulativeYieldFP`, there is a loop that runs based on the `hoursDelta` value which is calculated from user input `timeDelta`. If the `hoursDelta` value is large, the loop may consume an excessive amount of gas, which may result in an out-of-gas error. It may also allow for a potential Denial-of-Service (DoS) attack.
A12: 3_2 | B12: 3 | C12: 2 | D12: 5 | E12: `getUpdatedHourlyYield`, `calcCumulativeYieldFP` | F12: Magic numbers | I12: In several places in the code, there are hardcoded values (like `FP32`, `1 hours`, `100`). These are often referred to as "magic numbers" and are generally discouraged because they can make code harder to understand and maintain. It would be better to declare these as named constants at the top of the contract.
A13: 3_3 | B13: 3 | C13: 3 | D13: 1 | E13: _withdrawHourlyBond | F13: Underflow vulnerability | I13: In function _withdrawHourlyBond, there is a potential underflow when subtracting the 'amount' from 'bond.amount'. If 'amount' is greater than 'bond.amount', this operation will underflow and lead to an incorrect calculation. We need to add a require statement to ensure 'amount' is less than or equal to 'bond.amount'.
... A91: 25_3 | B91: 25 | C91: 3 | D91: 1 | E91: _updateUserRewards | F91: Arithmetic Precision Loss | I91: In the _updateUserRewards function, you are calculating the accumulated rewards for a user. The calculation involves a division operation at the end (`_balanceOf[user] * (rewardsPerToken_.accumulated - userRewards_.checkpoint) / 1e18`). This operation might lead to a precision loss because of the integer division, which in turn might lead to small inaccuracies in the rewards assigned to a user. This issue might be insignificant for large balances and rewards but could potentially be more noticeable for small balances and rewards.
A92: 29_1 | B92: 29 | C92: 1 | D92: 1 | E92: flashSwap | F92: Missing Input Validation
A93: 29_1 | B93: 29 | C93: 1 | D93: 2 | E93: burn | F93: Arithmetic Underflow
A94: 29_1 | B94: 29 | C94: 1 | D94: 3 | E94: burnSingle | F94: Arithmetic Underflow
A95: 29_1 | B95: 29 | C95: 1 | D95: 4 | E95: swap | F95: Arithmetic Underflow
A96: 29_1 | B96: 29 | C96: 1 | D96: 5 | E96: burnSingle | F96: Missing Input Validation
A97: 29_3 | B97: 29 | C97: 3 | D97: 1 | E97: `mint`, `burn`, `burnSingle`, `swap`, `flashSwap` | F97: Reentrancy Bug** | I97: The lock modifier used in these functions is meant to prevent reentrancy attacks, but it can potentially be bypassed. The `unlocked` variable is initially set to `1` and is changed to `2` at the start of the function execution. However, there's no guarantee that it will always be `1` before the function is called. An attacker can potentially manipulate the state of the contract to make `unlocked == 2` which can then bypass the reentrancy guard and allow for reentrancy attacks.
A98: 29_3 | B98: 29 | C98: 3 | D98: 2 | E98: `_mul`, `_div` | F98: Integer Overflow and Underflow** | I98: Solidity does not handle overflows and underflows automatically. This might lead to unexpected behavior if not handled correctly. Consider using SafeMath or Solidity 0.8.0 or later to handle these operations.
